(B)0[?1049h[1;16r[m[4l[H[JEvery 1.0s: docker logs chatbot -f[1;179Hniayesh: Sun Jun  9 13:27:06 2024[3;1HError response from daemon: No such container: chatbot[16;211H[1;206H7[16;211H[1;206H8[16;211H[1;205H10[3dTraceback (most recent call last):[K[4;3HFile "/usr/local/lib/python3.9/runpy.py", line 197, in _run_module_as_main[5;5Hreturn _run_code(code, main_globals, None,[6;3HFile "/usr/local/lib/python3.9/runpy.py", line 87, in _run_code[7;5Hexec(code, run_globals)[8;3HFile "/usr/local/lib/python3.9/site-packages/flask/__main__.py", line 3, in <module>[9;5Hmain()[10;3HFile "/usr/local/lib/python3.9/site-packages/flask/cli.py", line 1064, in main[11;5Hcli.main()[12;3HFile "/usr/local/lib/python3.9/site-packages/click/core.py", line 1078, in main[13;5Hrv = self.invoke(ctx)[14;3HFile "/usr/local/lib/python3.9/site-packages/click/core.py", line 1688, in invoke[15;5Hreturn _process_result(sub_ctx.command.invoke(sub_ctx))[16;3HFile "/usr/local/lib/python3.9/site-packages/click/core.py", line 1434, in invoke[211G[4d[J[1;206H4[3dError response from daemon: No such container: chatbot[16;211H[1;206H5[16;211H[1;206H6[16;211H[16;1H[?1049l[?1l>